2025-02-18 14:29:06 - WARNING: {'<pad>': 0, '<suc>': 1, 'monomer': 2, 'organic': 3, 'inorganic': 4, 'condition': 5, 'polymer_family': 6, 'syn_method': 7, 'prop_name': 8, 'prop_value': 9, 'ref_exp': 10, 'char_method': 11, 'polymer': 12, 'material_amount': 13, 'composite': 14, 'other_material': 15}
2025-02-18 14:29:06 - INFO: Building Model
2025-02-18 14:29:06 - WARNING: 2025-02-18 14:29:06 - INFO: Building Model
2025-02-18 14:29:13 - WARNING: Traceback (most recent call last):
  File "/home/antrieu/miniconda3/envs/py38_W2NER-main/lib/python3.8/site-packages/sqlalchemy/engine/base.py", line 1967, in _exec_single_context
    self.dialect.do_execute(
  File "/home/antrieu/miniconda3/envs/py38_W2NER-main/lib/python3.8/site-packages/sqlalchemy/engine/default.py", line 941, in do_execute
    cursor.execute(statement, parameters)
psycopg2.errors.UndefinedColumn: column users.fullname does not exist
LINE 1: ..., users.hashed_password AS users_hashed_password, users.full...
                                                             ^


The above exception was the direct cause of the following exception:

Traceback (most recent call last):
  File "/home/antrieu/drive/RIKEN/dev_tasks.py", line 115, in process_pdf_task
    user = user_crud.get_user(db,user_id)
  File "/home/antrieu/drive/RIKEN/crud/psql/user.py", line 28, in get_user
    return db.query(User).filter(User.id == user_id).first()
  File "/home/antrieu/miniconda3/envs/py38_W2NER-main/lib/python3.8/site-packages/sqlalchemy/orm/query.py", line 2728, in first
    return self.limit(1)._iter().first()  # type: ignore
  File "/home/antrieu/miniconda3/envs/py38_W2NER-main/lib/python3.8/site-packages/sqlalchemy/orm/query.py", line 2827, in _iter
    result: Union[ScalarResult[_T], Result[_T]] = self.session.execute(
  File "/home/antrieu/miniconda3/envs/py38_W2NER-main/lib/python3.8/site-packages/sqlalchemy/orm/session.py", line 2362, in execute
    return self._execute_internal(
  File "/home/antrieu/miniconda3/envs/py38_W2NER-main/lib/python3.8/site-packages/sqlalchemy/orm/session.py", line 2247, in _execute_internal
    result: Result[Any] = compile_state_cls.orm_execute_statement(
  File "/home/antrieu/miniconda3/envs/py38_W2NER-main/lib/python3.8/site-packages/sqlalchemy/orm/context.py", line 293, in orm_execute_statement
    result = conn.execute(
  File "/home/antrieu/miniconda3/envs/py38_W2NER-main/lib/python3.8/site-packages/sqlalchemy/engine/base.py", line 1418, in execute
    return meth(
  File "/home/antrieu/miniconda3/envs/py38_W2NER-main/lib/python3.8/site-packages/sqlalchemy/sql/elements.py", line 515, in _execute_on_connection
    return connection._execute_clauseelement(
  File "/home/antrieu/miniconda3/envs/py38_W2NER-main/lib/python3.8/site-packages/sqlalchemy/engine/base.py", line 1640, in _execute_clauseelement
    ret = self._execute_context(
  File "/home/antrieu/miniconda3/envs/py38_W2NER-main/lib/python3.8/site-packages/sqlalchemy/engine/base.py", line 1846, in _execute_context
    return self._exec_single_context(
  File "/home/antrieu/miniconda3/envs/py38_W2NER-main/lib/python3.8/site-packages/sqlalchemy/engine/base.py", line 1986, in _exec_single_context
    self._handle_dbapi_exception(
  File "/home/antrieu/miniconda3/envs/py38_W2NER-main/lib/python3.8/site-packages/sqlalchemy/engine/base.py", line 2355, in _handle_dbapi_exception
    raise sqlalchemy_exception.with_traceback(exc_info[2]) from e
  File "/home/antrieu/miniconda3/envs/py38_W2NER-main/lib/python3.8/site-packages/sqlalchemy/engine/base.py", line 1967, in _exec_single_context
    self.dialect.do_execute(
  File "/home/antrieu/miniconda3/envs/py38_W2NER-main/lib/python3.8/site-packages/sqlalchemy/engine/default.py", line 941, in do_execute
    cursor.execute(statement, parameters)
sqlalchemy.exc.ProgrammingError: (psycopg2.errors.UndefinedColumn) column users.fullname does not exist
LINE 1: ..., users.hashed_password AS users_hashed_password, users.full...
                                                             ^

[SQL: SELECT users.id AS users_id, users.username AS users_username, users.email AS users_email, users.hashed_password AS users_hashed_password, users.fullname AS users_fullname, users.address AS users_address, users.phone AS users_phone, users.workplace AS users_workplace 
FROM users 
WHERE users.id = %(id_1)s 
 LIMIT %(param_1)s]
[parameters: {'id_1': 6492, 'param_1': 1}]
(Background on this error at: https://sqlalche.me/e/20/f405)
2025-02-18 14:29:13 - ERROR: Task dev_tasks.process_pdf_task[b654882d-adf1-4fa6-b528-07afd8378575] raised unexpected: InternalError('(psycopg2.errors.InFailedSqlTransaction) current transaction is aborted, commands ignored until end of transaction block\n')
Traceback (most recent call last):
  File "/home/antrieu/miniconda3/envs/py38_W2NER-main/lib/python3.8/site-packages/sqlalchemy/engine/base.py", line 1967, in _exec_single_context
    self.dialect.do_execute(
  File "/home/antrieu/miniconda3/envs/py38_W2NER-main/lib/python3.8/site-packages/sqlalchemy/engine/default.py", line 941, in do_execute
    cursor.execute(statement, parameters)
psycopg2.errors.UndefinedColumn: column users.fullname does not exist
LINE 1: ..., users.hashed_password AS users_hashed_password, users.full...
                                                             ^


The above exception was the direct cause of the following exception:

Traceback (most recent call last):
  File "/home/antrieu/drive/RIKEN/dev_tasks.py", line 115, in process_pdf_task
    user = user_crud.get_user(db,user_id)
  File "/home/antrieu/drive/RIKEN/crud/psql/user.py", line 28, in get_user
    return db.query(User).filter(User.id == user_id).first()
  File "/home/antrieu/miniconda3/envs/py38_W2NER-main/lib/python3.8/site-packages/sqlalchemy/orm/query.py", line 2728, in first
    return self.limit(1)._iter().first()  # type: ignore
  File "/home/antrieu/miniconda3/envs/py38_W2NER-main/lib/python3.8/site-packages/sqlalchemy/orm/query.py", line 2827, in _iter
    result: Union[ScalarResult[_T], Result[_T]] = self.session.execute(
  File "/home/antrieu/miniconda3/envs/py38_W2NER-main/lib/python3.8/site-packages/sqlalchemy/orm/session.py", line 2362, in execute
    return self._execute_internal(
  File "/home/antrieu/miniconda3/envs/py38_W2NER-main/lib/python3.8/site-packages/sqlalchemy/orm/session.py", line 2247, in _execute_internal
    result: Result[Any] = compile_state_cls.orm_execute_statement(
  File "/home/antrieu/miniconda3/envs/py38_W2NER-main/lib/python3.8/site-packages/sqlalchemy/orm/context.py", line 293, in orm_execute_statement
    result = conn.execute(
  File "/home/antrieu/miniconda3/envs/py38_W2NER-main/lib/python3.8/site-packages/sqlalchemy/engine/base.py", line 1418, in execute
    return meth(
  File "/home/antrieu/miniconda3/envs/py38_W2NER-main/lib/python3.8/site-packages/sqlalchemy/sql/elements.py", line 515, in _execute_on_connection
    return connection._execute_clauseelement(
  File "/home/antrieu/miniconda3/envs/py38_W2NER-main/lib/python3.8/site-packages/sqlalchemy/engine/base.py", line 1640, in _execute_clauseelement
    ret = self._execute_context(
  File "/home/antrieu/miniconda3/envs/py38_W2NER-main/lib/python3.8/site-packages/sqlalchemy/engine/base.py", line 1846, in _execute_context
    return self._exec_single_context(
  File "/home/antrieu/miniconda3/envs/py38_W2NER-main/lib/python3.8/site-packages/sqlalchemy/engine/base.py", line 1986, in _exec_single_context
    self._handle_dbapi_exception(
  File "/home/antrieu/miniconda3/envs/py38_W2NER-main/lib/python3.8/site-packages/sqlalchemy/engine/base.py", line 2355, in _handle_dbapi_exception
    raise sqlalchemy_exception.with_traceback(exc_info[2]) from e
  File "/home/antrieu/miniconda3/envs/py38_W2NER-main/lib/python3.8/site-packages/sqlalchemy/engine/base.py", line 1967, in _exec_single_context
    self.dialect.do_execute(
  File "/home/antrieu/miniconda3/envs/py38_W2NER-main/lib/python3.8/site-packages/sqlalchemy/engine/default.py", line 941, in do_execute
    cursor.execute(statement, parameters)
sqlalchemy.exc.ProgrammingError: (psycopg2.errors.UndefinedColumn) column users.fullname does not exist
LINE 1: ..., users.hashed_password AS users_hashed_password, users.full...
                                                             ^

[SQL: SELECT users.id AS users_id, users.username AS users_username, users.email AS users_email, users.hashed_password AS users_hashed_password, users.fullname AS users_fullname, users.address AS users_address, users.phone AS users_phone, users.workplace AS users_workplace 
FROM users 
WHERE users.id = %(id_1)s 
 LIMIT %(param_1)s]
[parameters: {'id_1': 6492, 'param_1': 1}]
(Background on this error at: https://sqlalche.me/e/20/f405)

During handling of the above exception, another exception occurred:

Traceback (most recent call last):
  File "/home/antrieu/miniconda3/envs/py38_W2NER-main/lib/python3.8/site-packages/sqlalchemy/engine/base.py", line 1967, in _exec_single_context
    self.dialect.do_execute(
  File "/home/antrieu/miniconda3/envs/py38_W2NER-main/lib/python3.8/site-packages/sqlalchemy/engine/default.py", line 941, in do_execute
    cursor.execute(statement, parameters)
psycopg2.errors.InFailedSqlTransaction: current transaction is aborted, commands ignored until end of transaction block


The above exception was the direct cause of the following exception:

Traceback (most recent call last):
  File "/home/antrieu/miniconda3/envs/py38_W2NER-main/lib/python3.8/site-packages/celery/app/trace.py", line 453, in trace_task
    R = retval = fun(*args, **kwargs)
  File "/home/antrieu/miniconda3/envs/py38_W2NER-main/lib/python3.8/site-packages/celery/app/trace.py", line 736, in __protected_call__
    return self.run(*args, **kwargs)
  File "/home/antrieu/drive/RIKEN/dev_tasks.py", line 182, in process_pdf_task
    current_doc = document_crud.get_document(db,doc_id)
  File "/home/antrieu/drive/RIKEN/crud/psql/document.py", line 95, in get_document
    return db.query(Document).filter(Document.id == document_id).first()
  File "/home/antrieu/miniconda3/envs/py38_W2NER-main/lib/python3.8/site-packages/sqlalchemy/orm/query.py", line 2728, in first
    return self.limit(1)._iter().first()  # type: ignore
  File "/home/antrieu/miniconda3/envs/py38_W2NER-main/lib/python3.8/site-packages/sqlalchemy/orm/query.py", line 2827, in _iter
    result: Union[ScalarResult[_T], Result[_T]] = self.session.execute(
  File "/home/antrieu/miniconda3/envs/py38_W2NER-main/lib/python3.8/site-packages/sqlalchemy/orm/session.py", line 2362, in execute
    return self._execute_internal(
  File "/home/antrieu/miniconda3/envs/py38_W2NER-main/lib/python3.8/site-packages/sqlalchemy/orm/session.py", line 2247, in _execute_internal
    result: Result[Any] = compile_state_cls.orm_execute_statement(
  File "/home/antrieu/miniconda3/envs/py38_W2NER-main/lib/python3.8/site-packages/sqlalchemy/orm/context.py", line 293, in orm_execute_statement
    result = conn.execute(
  File "/home/antrieu/miniconda3/envs/py38_W2NER-main/lib/python3.8/site-packages/sqlalchemy/engine/base.py", line 1418, in execute
    return meth(
  File "/home/antrieu/miniconda3/envs/py38_W2NER-main/lib/python3.8/site-packages/sqlalchemy/sql/elements.py", line 515, in _execute_on_connection
    return connection._execute_clauseelement(
  File "/home/antrieu/miniconda3/envs/py38_W2NER-main/lib/python3.8/site-packages/sqlalchemy/engine/base.py", line 1640, in _execute_clauseelement
    ret = self._execute_context(
  File "/home/antrieu/miniconda3/envs/py38_W2NER-main/lib/python3.8/site-packages/sqlalchemy/engine/base.py", line 1846, in _execute_context
    return self._exec_single_context(
  File "/home/antrieu/miniconda3/envs/py38_W2NER-main/lib/python3.8/site-packages/sqlalchemy/engine/base.py", line 1986, in _exec_single_context
    self._handle_dbapi_exception(
  File "/home/antrieu/miniconda3/envs/py38_W2NER-main/lib/python3.8/site-packages/sqlalchemy/engine/base.py", line 2355, in _handle_dbapi_exception
    raise sqlalchemy_exception.with_traceback(exc_info[2]) from e
  File "/home/antrieu/miniconda3/envs/py38_W2NER-main/lib/python3.8/site-packages/sqlalchemy/engine/base.py", line 1967, in _exec_single_context
    self.dialect.do_execute(
  File "/home/antrieu/miniconda3/envs/py38_W2NER-main/lib/python3.8/site-packages/sqlalchemy/engine/default.py", line 941, in do_execute
    cursor.execute(statement, parameters)
sqlalchemy.exc.InternalError: (psycopg2.errors.InFailedSqlTransaction) current transaction is aborted, commands ignored until end of transaction block

[SQL: SELECT documents.id AS documents_id, documents."Paragraphs" AS "documents_Paragraphs", documents."UploadTime" AS "documents_UploadTime", documents."FilePath" AS "documents_FilePath", documents."FileName" AS "documents_FileName", documents."Entities" AS "documents_Entities", documents."Relation" AS "documents_Relation", documents."Event" AS "documents_Event", documents."Position" AS "documents_Position", documents."UserID" AS "documents_UserID", documents."StatisticInfor" AS "documents_StatisticInfor" 
FROM documents 
WHERE documents.id = %(id_1)s 
 LIMIT %(param_1)s]
[parameters: {'id_1': 37609859, 'param_1': 1}]
(Background on this error at: https://sqlalche.me/e/20/2j85)
2025-02-18 14:29:13 - WARNING: 2025-02-18 14:29:13 - ERROR: Task dev_tasks.process_pdf_task[b654882d-adf1-4fa6-b528-07afd8378575] raised unexpected: InternalError('(psycopg2.errors.InFailedSqlTransaction) current transaction is aborted, commands ignored until end of transaction block\n')
Traceback (most recent call last):
  File "/home/antrieu/miniconda3/envs/py38_W2NER-main/lib/python3.8/site-packages/sqlalchemy/engine/base.py", line 1967, in _exec_single_context
    self.dialect.do_execute(
  File "/home/antrieu/miniconda3/envs/py38_W2NER-main/lib/python3.8/site-packages/sqlalchemy/engine/default.py", line 941, in do_execute
    cursor.execute(statement, parameters)
psycopg2.errors.UndefinedColumn: column users.fullname does not exist
LINE 1: ..., users.hashed_password AS users_hashed_password, users.full...
                                                             ^


The above exception was the direct cause of the following exception:

Traceback (most recent call last):
  File "/home/antrieu/drive/RIKEN/dev_tasks.py", line 115, in process_pdf_task
    user = user_crud.get_user(db,user_id)
  File "/home/antrieu/drive/RIKEN/crud/psql/user.py", line 28, in get_user
    return db.query(User).filter(User.id == user_id).first()
  File "/home/antrieu/miniconda3/envs/py38_W2NER-main/lib/python3.8/site-packages/sqlalchemy/orm/query.py", line 2728, in first
    return self.limit(1)._iter().first()  # type: ignore
  File "/home/antrieu/miniconda3/envs/py38_W2NER-main/lib/python3.8/site-packages/sqlalchemy/orm/query.py", line 2827, in _iter
    result: Union[ScalarResult[_T], Result[_T]] = self.session.execute(
  File "/home/antrieu/miniconda3/envs/py38_W2NER-main/lib/python3.8/site-packages/sqlalchemy/orm/session.py", line 2362, in execute
    return self._execute_internal(
  File "/home/antrieu/miniconda3/envs/py38_W2NER-main/lib/python3.8/site-packages/sqlalchemy/orm/session.py", line 2247, in _execute_internal
    result: Result[Any] = compile_state_cls.orm_execute_statement(
  File "/home/antrieu/miniconda3/envs/py38_W2NER-main/lib/python3.8/site-packages/sqlalchemy/orm/context.py", line 293, in orm_execute_statement
    result = conn.execute(
  File "/home/antrieu/miniconda3/envs/py38_W2NER-main/lib/python3.8/site-packages/sqlalchemy/engine/base.py", line 1418, in execute
    return meth(
  File "/home/antrieu/miniconda3/envs/py38_W2NER-main/lib/python3.8/site-packages/sqlalchemy/sql/elements.py", line 515, in _execute_on_connection
    return connection._execute_clauseelement(
  File "/home/antrieu/miniconda3/envs/py38_W2NER-main/lib/python3.8/site-packages/sqlalchemy/engine/base.py", line 1640, in _execute_clauseelement
    ret = self._execute_context(
  File "/home/antrieu/miniconda3/envs/py38_W2NER-main/lib/python3.8/site-packages/sqlalchemy/engine/base.py", line 1846, in _execute_context
    return self._exec_single_context(
  File "/home/antrieu/miniconda3/envs/py38_W2NER-main/lib/python3.8/site-packages/sqlalchemy/engine/base.py", line 1986, in _exec_single_context
    self._handle_dbapi_exception(
  File "/home/antrieu/miniconda3/envs/py38_W2NER-main/lib/python3.8/site-packages/sqlalchemy/engine/base.py", line 2355, in _handle_dbapi_exception
    raise sqlalchemy_exception.with_traceback(exc_info[2]) from e
  File "/home/antrieu/miniconda3/envs/py38_W2NER-main/lib/python3.8/site-packages/sqlalchemy/engine/base.py", line 1967, in _exec_single_context
    self.dialect.do_execute(
  File "/home/antrieu/miniconda3/envs/py38_W2NER-main/lib/python3.8/site-packages/sqlalchemy/engine/default.py", line 941, in do_execute
    cursor.execute(statement, parameters)
sqlalchemy.exc.ProgrammingError: (psycopg2.errors.UndefinedColumn) column users.fullname does not exist
LINE 1: ..., users.hashed_password AS users_hashed_password, users.full...
                                                             ^

[SQL: SELECT users.id AS users_id, users.username AS users_username, users.email AS users_email, users.hashed_password AS users_hashed_password, users.fullname AS users_fullname, users.address AS users_address, users.phone AS users_phone, users.workplace AS users_workplace 
FROM users 
WHERE users.id = %(id_1)s 
 LIMIT %(param_1)s]
[parameters: {'id_1': 6492, 'param_1': 1}]
(Background on this error at: https://sqlalche.me/e/20/f405)

During handling of the above exception, another exception occurred:

Traceback (most recent call last):
  File "/home/antrieu/miniconda3/envs/py38_W2NER-main/lib/python3.8/site-packages/sqlalchemy/engine/base.py", line 1967, in _exec_single_context
    self.dialect.do_execute(
  File "/home/antrieu/miniconda3/envs/py38_W2NER-main/lib/python3.8/site-packages/sqlalchemy/engine/default.py", line 941, in do_execute
    cursor.execute(statement, parameters)
psycopg2.errors.InFailedSqlTransaction: current transaction is aborted, commands ignored until end of transaction block


The above exception was the direct cause of the following exception:

Traceback (most recent call last):
  File "/home/antrieu/miniconda3/envs/py38_W2NER-main/lib/python3.8/site-packages/celery/app/trace.py", line 453, in trace_task
    R = retval = fun(*args, **kwargs)
  File "/home/antrieu/miniconda3/envs/py38_W2NER-main/lib/python3.8/site-packages/celery/app/trace.py", line 736, in __protected_call__
    return self.run(*args, **kwargs)
  File "/home/antrieu/drive/RIKEN/dev_tasks.py", line 182, in process_pdf_task
    current_doc = document_crud.get_document(db,doc_id)
  File "/home/antrieu/drive/RIKEN/crud/psql/document.py", line 95, in get_document
    return db.query(Document).filter(Document.id == document_id).first()
  File "/home/antrieu/miniconda3/envs/py38_W2NER-main/lib/python3.8/site-packages/sqlalchemy/orm/query.py", line 2728, in first
    return self.limit(1)._iter().first()  # type: ignore
  File "/home/antrieu/miniconda3/envs/py38_W2NER-main/lib/python3.8/site-packages/sqlalchemy/orm/query.py", line 2827, in _iter
    result: Union[ScalarResult[_T], Result[_T]] = self.session.execute(
  File "/home/antrieu/miniconda3/envs/py38_W2NER-main/lib/python3.8/site-packages/sqlalchemy/orm/session.py", line 2362, in execute
    return self._execute_internal(
  File "/home/antrieu/miniconda3/envs/py38_W2NER-main/lib/python3.8/site-packages/sqlalchemy/orm/session.py", line 2247, in _execute_internal
    result: Result[Any] = compile_state_cls.orm_execute_statement(
  File "/home/antrieu/miniconda3/envs/py38_W2NER-main/lib/python3.8/site-packages/sqlalchemy/orm/context.py", line 293, in orm_execute_statement
    result = conn.execute(
  File "/home/antrieu/miniconda3/envs/py38_W2NER-main/lib/python3.8/site-packages/sqlalchemy/engine/base.py", line 1418, in execute
    return meth(
  File "/home/antrieu/miniconda3/envs/py38_W2NER-main/lib/python3.8/site-packages/sqlalchemy/sql/elements.py", line 515, in _execute_on_connection
    return connection._execute_clauseelement(
  File "/home/antrieu/miniconda3/envs/py38_W2NER-main/lib/python3.8/site-packages/sqlalchemy/engine/base.py", line 1640, in _execute_clauseelement
    ret = self._execute_context(
  File "/home/antrieu/miniconda3/envs/py38_W2NER-main/lib/python3.8/site-packages/sqlalchemy/engine/base.py", line 1846, in _execute_context
    return self._exec_single_context(
  File "/home/antrieu/miniconda3/envs/py38_W2NER-main/lib/python3.8/site-packages/sqlalchemy/engine/base.py", line 1986, in _exec_single_context
    self._handle_dbapi_exception(
  File "/home/antrieu/miniconda3/envs/py38_W2NER-main/lib/python3.8/site-packages/sqlalchemy/engine/base.py", line 2355, in _handle_dbapi_exception
    raise sqlalchemy_exception.with_traceback(exc_info[2]) from e
  File "/home/antrieu/miniconda3/envs/py38_W2NER-main/lib/python3.8/site-packages/sqlalchemy/engine/base.py", line 1967, in _exec_single_context
    self.dialect.do_execute(
  File "/home/antrieu/miniconda3/envs/py38_W2NER-main/lib/python3.8/site-packages/sqlalchemy/engine/default.py", line 941, in do_execute
    cursor.execute(statement, parameters)
sqlalchemy.exc.InternalError: (psycopg2.errors.InFailedSqlTransaction) current transaction is aborted, commands ignored until end of transaction block

[SQL: SELECT documents.id AS documents_id, documents."Paragraphs" AS "documents_Paragraphs", documents."UploadTime" AS "documents_UploadTime", documents."FilePath" AS "documents_FilePath", documents."FileName" AS "documents_FileName", documents."Entities" AS "documents_Entities", documents."Relation" AS "documents_Relation", documents."Event" AS "documents_Event", documents."Position" AS "documents_Position", documents."UserID" AS "documents_UserID", documents."StatisticInfor" AS "documents_StatisticInfor" 
FROM documents 
WHERE documents.id = %(id_1)s 
 LIMIT %(param_1)s]
[parameters: {'id_1': 37609859, 'param_1': 1}]
(Background on this error at: https://sqlalche.me/e/20/2j85)
